<?xml version="1.0"?>
<robot name="bongo_board_skeleton">
    <link name="world" />

    <link name="board">
        <inertial>
            <mass value="0.453" />
            <origin xyz="0 0 0" rpy="0 0 0"/>
            <inertia ixx="0.003398" ixy="0" ixz="0" iyy="0.000849" iyz="0" izz="0.004247" />
        </inertial>
        <visual>
            <origin xyz="0 0 0" rpy="0 0 0" />
            <geometry>
                <box size="0.15 0.4 0.01" />
            </geometry>
        </visual>
        <collision>
            <origin xyz="0 0 0" rpy="0 0 0" />
            <geometry>
                <box size="0.15 0.4 0.01" />
            </geometry>
        </collision>
    </link>

    <link name="support">
        <inertial>
            <mass value="0.151" />
            <origin xyz="0 0 -0.04" rpy="0 1.57 0" />
            <inertia ixx="0.000067" ixy="0" ixz="0" iyy="0.0000618" iyz="0" izz="0.0000618" />
        </inertial>
        <visual>
            <origin xyz="0 0 -0.02" rpy="0 1.57 0" />
            <geometry>
                <cylinder length="0.15" radius="0.015"/>
            </geometry>
        </visual>
        <collision>
            <origin xyz="0 0 -0.02" rpy="0 1.57 0" />
            <geometry>
                <cylinder length="0.15" radius="0.015"/>
            </geometry>
        </collision>
    </link>


    <joint name="jt1" type="floating">
        <parent link="world"/>
        <child link="support"/>
        <origin rpy="0 0 0" xyz="0 0 -0.31"/>
    </joint>

    <joint name="jt2" type="fixed">
        <parent link="support"/>
        <child link="board"/>
    </joint>

</robot>